Workbook

Sheet GRE
A1: BOOK_CURRENCY_CODE | B1: Portfolio | C1: AS_OF_DATE | D1: Daily PL | E1: HOLDING_VALUE_RPT_CCY_AMT | F1: CASH_BALANCE_AMT | G1: EXTERNAL_CF_AMT | H1: NET_ASSET_VALUE_AMT | I1: Return | J1: Index | M1: Benchmark | N1: Benchmark Transfer | O1: Absolute Bench Inc | P1: Murex excess return | Q1: Corrected FTP cost | R1: Excess return after correction | S1: Bench Daily
C2: 46203 | E2: 4.392226e+09 | F2: -3713455.1 | H2: =E2+F2 -> 4.3885125e+09 | J2: 100
A3: USD | B3: LAM_STG_GRE | C3: 46204 | D3: -435400.96 | E3: 4.3918403e+09 | F3: -3713455.1 | G3: =-(E2+D3-E3) -> 49729.57 | H3: =E3+F3 -> 4.3881269e+09 | I3: =(H3-H2-G3)/(H2+G3) -> -9.9212665e-05 | J3: =J2*(1+I3) -> 99.990079 | K3: =H3-H2-G3 -> -435400.96 | L3: =K3-D3 -> -3.8126018e-08 | O3: =-(H2+G3)*S3 -> -839055.53 | P3: =D3+O3 -> -1274456.5 | Q3: =O3 -> -839055.53 | R3: =D3+Q3 -> -1274456.5 | S3: 0.00019119144
A4: USD | B4: LAM_STG_GRE | C4: 46205 | D4: 31446.7 | E4: 4.3915206e+09 | F4: -3713455.1 | G4: =-(E3+D4-E4) -> -351169.72 | H4: =E4+F4 -> 4.3878071e+09 | I4: =(H4-H3-G4)/(H3+G4) -> 7.1668887e-06 | J4: =J3*(1+I4) -> 99.990795 | K4: =H4-H3-G4 -> 31446.7 | L4: =K4-D4 -> -1.9073559e-07 | O4: =-(H3+G4)*S4 -> -480611.4 | P4: =D4+O4 -> -449164.7 | Q4: =O4 -> -480611.4 | R4: =D4+Q4 -> -449164.7 | S4: 0.00010953418
A5: USD | B5: LAM_STG_GRE | C5: 46206 | D5: 424584.26 | E5: 4.3918753e+09 | F5: -3713455.1 | G5: =-(E4+D5-E5) -> -69837.16 | H5: =E5+F5 -> 4.3881619e+09 | I5: =(H5-H4-G5)/(H4+G5) -> 9.6766108e-05 | J5: =J4*(1+I5) -> 100.00047 | K5: =H5-H4-G5 -> 424584.26 | L5: =K5-D5 -> 2.2887252e-07 | O5: =-(H4+G5)*S5 -> -478130.23 | P5: =D5+O5 -> -53545.969 | Q5: =O5 -> -478130.23 | R5: =D5+Q5 -> -53545.969 | S5: 0.00010896966
A6: USD | B6: LAM_STG_GRE | C6: 46207 | D6: -118395.04 | E6: 4.391757e+09 | F6: -3713455.1 | G6: =-(E5+D6-E6) -> 0 | H6: =E6+F6 -> 4.3880435e+09 | I6: =(H6-H5-G6)/(H5+G6) -> -2.6980554e-05 | J6: =J5*(1+I6) -> 99.997773 | K6: =H6-H5-G6 -> -118395.04 | L6: =K6-D6 -> 3.814057e-08 | O6: =-(H5+G6)*S6 -> -480549.9 | P6: =D6+O6 -> -598944.94 | Q6: =O6 -> -480549.9 | R6: =D6+Q6 -> -598944.94 | S6: 0.00010951052
A7: USD | B7: LAM_STG_GRE | C7: 46208 | D7: 526493.77 | E7: 4.3922834e+09 | F7: -3713455.1 | G7: =-(E6+D7-E7) -> 0 | H7: =E7+F7 -> 4.38857e+09 | I7: =(H7-H6-G7)/(H6+G7) -> 0.00011998372 | J7: =J6*(1+I7) -> 100.00977 | K7: =H7-H6-G7 -> 526493.77 | L7: =K7-D7 -> 4.5774505e-07 | O7: =-(H6+G7)*S7 -> -480483.11 | P7: =D7+O7 -> 46010.66 | Q7: =O7 -> -480483.11 | R7: =D7+Q7 -> 46010.66 | S7: 0.00010949826
A8: USD | B8: LAM_STG_GRE | C8: 46209 | D8: 485982.39 | E8: 4.4447964e+09 | F8: -3713455.1 | G8: =-(E7+D8-E8) -> 52027012 | H8: =E8+F8 -> 4.441083e+09 | I8: =(H8-H7-G8)/(H7+G8) -> 0.00010944078 | J8: =J7*(1+I8) -> 100.02072 | K8: =H8-H7-G8 -> 485982.39 | L8: =K8-D8 -> 3.4330878e-07 | O8: =-(H7+G8)*S8 -> -492140.58 | P8: =D8+O8 -> -6158.1852 | Q8: =O8 -> -492140.58 | R8: =D8+Q8 -> -6158.1852 | S8: 0.00011082757
A9: USD | B9: LAM_STG_GRE | C9: 46210 | D9: 2481615.6 | E9: 4.4472781e+09 | F9: -3713455.1 | G9: =-(E8+D9-E9) -> -9.5367432e-07 | H9: =E9+F9 -> 4.4435646e+09 | I9: =(H9-H8-G9)/(H8+G9) -> 0.00055878614 | J9: =J8*(1+I9) -> 100.07661 | K9: =H9-H8-G9 -> 2481615.6 | L9: =K9-D9 -> 3.8137659e-07 | O9: =-(H8+G9)*S9 -> -494083.61 | P9: =D9+O9 -> 1987532 | Q9: =O9 -> -494083.61 | R9: =D9+Q9 -> 1987532 | S9: 0.00011125296
A10: USD | B10: LAM_STG_GRE | C10: 46211 | D10: 200356.01 | E10: 4.4398391e+09 | F10: -3713455.1 | G10: =-(E9+D10-E10) -> -7639311.3 | H10: =E10+F10 -> 4.4361256e+09 | I10: =(H10-H9-G10)/(H9+G10) -> 4.5166678e-05 | J10: =J9*(1+I10) -> 100.08113 | K10: =H10-H9-G10 -> 200356.01 | L10: =K10-D10 -> 2.2887252e-07 | O10: =-(H9+G10)*S10 -> -478911.41 | P10: =D10+O10 -> -278555.4 | Q10: =O10 -> -478911.41 | R10: =D10+Q10 -> -278555.4 | S10: 0.00010796201
A11: USD | B11: LAM_STG_GRE | C11: 46212 | D11: -78273.85 | E11: 4.5011356e+09 | F11: -3713455.1 | G11: =-(E10+D11-E11) -> 61374760 | H11: =E11+F11 -> 4.4974221e+09 | I11: =(H11-H10-G11)/(H10+G11) -> -1.7403856e-05 | J11: =J10*(1+I11) -> 100.07938 | K11: =H11-H10-G11 -> -78273.85 | L11: =K11-D11 -> -3.8146391e-07 | O11: =-(H10+G11)*S11 -> -474865.19 | P11: =D11+O11 -> -553139.04 | Q11: =O11 -> -474865.19 | R11: =D11+Q11 -> -553139.04 | S11: 0.00010558425
A12: USD | B12: LAM_STG_GRE | C12: 46213 | D12: 1058475.6 | E12: 4.5018445e+09 | F12: -3713455.1 | G12: =-(E11+D12-E12) -> -349514.37 | H12: =E12+F12 -> 4.4981311e+09 | I12: =(H12-H11-G12)/(H11+G12) -> 0.00023536992 | J12: =J11*(1+I12) -> 100.10294 | K12: =H12-H11-G12 -> 1058475.6 | L12: =K12-D12 -> 3.434252e-07 | O12: =-(H11+G12)*S12 -> -457527.93 | P12: =D12+O12 -> 600947.71 | Q12: =O12 -> -457527.93 | R12: =D12+Q12 -> 600947.71 | S12: 0.00010173906
A13: USD | B13: LAM_STG_GRE | C13: 46214 | D13: 417686.79 | E13: 4.5022622e+09 | F13: -3713455.1 | G13: =-(E12+D13-E13) -> 9.5367432e-07 | H13: =E13+F13 -> 4.4985488e+09 | I13: =(H13-H12-G13)/(H12+G13) -> 9.2857852e-05 | J13: =J12*(1+I13) -> 100.11224 | K13: =H13-H12-G13 -> 417686.79 | L13: =K13-D13 -> -3.8126018e-08 | O13: =-(H12+G13)*S13 -> -490811.16 | P13: =D13+O13 -> -73124.373 | Q13: =O13 -> -490811.16 | R13: =D13+Q13 -> -73124.373 | S13: 0.00010911446
A14: USD | B14: LAM_STG_GRE | C14: 46215 | D14: 415947.72 | E14: 4.5026782e+09 | F14: -3713455.1 | G14: =-(E13+D14-E14) -> 0.0099992752 | H14: =E14+F14 -> 4.4989647e+09 | I14: =(H14-H13-G14)/(H13+G14) -> 9.2462645e-05 | J14: =J13*(1+I14) -> 100.12149 | K14: =H14-H13-G14 -> 415947.72 | L14: =K14-D14 -> 2.6705675e-07 | O14: =-(H13+G14)*S14 -> -484091.58 | P14: =D14+O14 -> -68143.858 | Q14: =O14 -> -484091.58 | R14: =D14+Q14 -> -68143.858 | S14: 0.00010761061
... A53: USD | B53: LAM_STG_GRE | C53: 46254 | D53: 1354835.5 | E53: 4.2400147e+09 | F53: -3713455.1 | G53: =-(E52+D53-E53) -> -128410.97 | H53: =E53+F53 -> 4.2363012e+09 | I53: =(H53-H52-G53)/(H52+G53) -> 0.00031991798 | J53: =J52*(1+I53) -> 100.64447 | K53: =H53-H52-G53 -> 1354835.5 | L53: =K53-D53 -> 1.9092113e-08 | O53: =-(H52+G53)*S53 -> -475485.7 | P53: =D53+O53 -> 879349.78 | Q53: =O53 -> -475485.7 | R53: =D53+Q53 -> 879349.78 | S53: 0.00011227667
A54: USD | B54: LAM_STG_GRE | C54: 46255 | D54: 232372.47 | E54: 4.2363742e+09 | F54: 159359.19 | H54: =E54+F54 -> 4.2365336e+09 | I54: =(H54-H53-G54)/(H53+G54) -> 5.4852679e-05 | J54: =J53*(1+I54) -> 100.64999 | K54: =H54-H53-G54 -> 232372.47 | L54: =K54-D54 -> -7.6834112e-09 | O54: =-(H53+G54)*S54 -> -475637.81 | P54: =D54+O54 -> -243265.34 | Q54: =O54 -> -475637.81 | R54: =D54+Q54 -> -243265.34 | S54: =S53 -> 0.00011227667
A55: USD | B55: LAM_STG_GRE | C55: 46258 | D55: 2731194 | E55: 4.2396714e+09 | F55: -346925.25 | G55: 59658.5 | H55: =E55+F55 -> 4.2393244e+09 | I55: =(H55-H54-G55)/(H54+G55) -> 0.00064466751 | J55: =J54*(1+I55) -> 100.71488 | K55: =H55-H54-G55 -> 2731194 | L55: =K55-D55 -> -1.8645078e-06 | O55: -700190.35 | P55: =D55+O55 -> 2031003.7 | Q55: =$Q$54*(C55-C54)*E55/E54 -> -1428024 | R55: =D55+Q55 -> 1303170
A56: USD | B56: LAM_STG_GRE | C56: 46259 | D56: -439167.8 | E56: 4.2376638e+09 | F56: 1241360 | G56: 19892.215 | H56: =E56+F56 -> 4.2389052e+09 | I56: =(H56-H55-G56)/(H55+G56) -> -0.00010359333 | J56: =J55*(1+I56) -> 100.70444 | K56: =H56-H55-G56 -> -439167.8 | L56: =K56-D56 -> 1.7364509e-06 | O56: -246789.82 | P56: =D56+O56 -> -685957.62 | Q56: =$Q$54*(C56-C55)*E56/E55 -> -475412.59 | R56: =D56+Q56 -> -914580.39
A57: USD | B57: LAM_STG_GRE | C57: 46260 | D57: 2902129.8 | E57: 4.2398515e+09 | F57: 1975656.2 | G57: 19894.232 | H57: =E57+F57 -> 4.2418272e+09 | I57: =(H57-H56-G57)/(H56+G57) -> 0.00068463815 | J57: =J56*(1+I57) -> 100.77339 | K57: =H57-H56-G57 -> 2902129.8 | L57: =K57-D57 -> 2.0861626e-07 | O57: -247436.67 | P57: =D57+O57 -> 2654693.1 | Q57: =$Q$54*(C57-C56)*E57/E56 -> -475883.36 | R57: =D57+Q57 -> 2426246.4
A58: USD | B58: LAM_STG_GRE | C58: 46261 | D58: 2451323.9 | E58: 4.2413303e+09 | F58: 2968088.8 | G58: 19896.251 | H58: =E58+F58 -> 4.2442984e+09 | I58: =(H58-H57-G58)/(H57+G58) -> 0.00057789069 | J58: =J57*(1+I58) -> 100.83163 | K58: =H58-H57-G58 -> 2451323.9 | L58: =K58-D58 -> 8.4517524e-07 | O58: -246217.92 | P58: =D58+O58 -> 2205106 | Q58: =$Q$54*(C58-C57)*E58/E57 -> -475803.71 | R58: =D58+Q58 -> 1975520.2
A59: USD | B59: LAM_STG_GRE | C59: 46262 | D59: 1842244.9 | E59: 4.2397713e+09 | F59: 6389305.5 | G59: 19898.267 | H59: =E59+F59 -> 4.2461606e+09 | I59: =(H59-H58-G59)/(H58+G59) -> 0.00043404966 | J59: =J58*(1+I59) -> 100.87539 | K59: =H59-H58-G59 -> 1842244.9 | L59: =K59-D59 -> -3.4729019e-06 | O59: -286226.67 | P59: =D59+O59 -> 1556018.3 | Q59: =$Q$54*(C59-C58)*E59/E58 -> -475462.97 | R59: =D59+Q59 -> 1366782
A60: USD | B60: LAM_STG_GRE | C60: 46265 | D60: 982191.94 | E60: 4.2262065e+09 | F60: 35324063 | G60: 14387793 | H60: =E60+F60 -> 4.2615305e+09 | I60: =(H60-H59-G60)/(H59+G60) -> 0.00023053181 | J60: =J59*(1+I60) -> 100.89865 | K60: =H60-H59-G60 -> 982191.94 | L60: =K60-D60 -> -4.1108578e-06 | O60: -700558.59 | P60: =D60+O60 -> 281633.35 | Q60: =$Q$54*(C60-C59)*E60/E59 -> -1422348.2 | R60: =D60+Q60 -> -440156.21
A61: USD | B61: LAM_STG_GRE | C61: 46266 | D61: 1423343.9 | E61: 4.1982377e+09 | F61: 67231995 | G61: 2515778.2 | H61: =E61+F61 -> 4.2654697e+09 | I61: =(H61-H60-G61)/(H60+G61) -> 0.00033380122 | J61: =J60*(1+I61) -> 100.93233 | K61: =H61-H60-G61 -> 1423343.9 | L61: =K61-D61 -> 6.5974891e-06 | O61: -247217.33 | P61: =D61+O61 -> 1176126.5 | Q61: =$Q$54*(C61-C60)*E61/E60 -> -472490.07 | R61: =D61+Q61 -> 950853.81
A62: USD | B62: LAM_STG_GRE | C62: 46267 | D62: -269323.09 | E62: 4.1356068e+09 | F62: 1.3191932e+08 | G62: 2325758.8 | H62: =E62+F62 -> 4.2675261e+09 | I62: =(H62-H61-G62)/(H61+G62) -> -6.3105903e-05 | J62: =J61*(1+I62) -> 100.92596 | K62: =H62-H61-G62 -> -269323.09 | L62: =K62-D62 -> 2.7325004e-06 | O62: -245731.39 | P62: =D62+O62 -> -515054.48 | Q62: =$Q$54*(C62-C61)*E62/E61 -> -468542.07 | R62: =D62+Q62 -> -737865.15
A63: USD | B63: LAM_STG_GRE | C63: 46268 | D63: -583892.18 | E63: 4.0516828e+09 | F63: 3.4040696e+08 | G63: 1.2514754e+08 | H63: =E63+F63 -> 4.3920898e+09 | I63: =(H63-H62-G63)/(H62+G63) -> -0.0001329241 | J63: =J62*(1+I63) -> 100.91254 | K63: =H63-H62-G63 -> -583892.18 | L63: =K63-D63 -> 2.7175993e-06 | O63: -243791.66 | P63: =D63+O63 -> -827683.83 | Q63: =$Q$54*(C63-C62)*E63/E62 -> -465985.68 | R63: =D63+Q63 -> -1049877.9
A64: USD | B64: LAM_STG_GRE | C64: 46269 | D64: 1239798.6 | E64: 4.0749066e+09 | F64: 3.1613555e+08 | G64: -2287369.9 | H64: =E64+F64 -> 4.3910422e+09 | I64: =(H64-H63-G64)/(H63+G64) -> 0.00028242698 | J64: =J63*(1+I64) -> 100.94104 | K64: =H64-H63-G64 -> 1239798.6 | L64: =K64-D64 -> -5.5842102e-06 | O64: -288016.65 | P64: =D64+O64 -> 951782 | Q64: =$Q$54*(C64-C63)*E64/E63 -> -478364.12 | R64: =D64+Q64 -> 761434.52
A65: USD | B65: LAM_STG_GRE | C65: 46273 | D65: -236155.48 | E65: 4.0527005e+09 | F65: 3.8202355e+08 | G65: 43918009 | H65: =E65+F65 -> 4.434724e+09 | I65: =(H65-H64-G65)/(H64+G65) -> -5.3248613e-05 | J65: =J64*(1+I65) -> 100.93567 | K65: =H65-H64-G65 -> -236155.48 | L65: =K65-D65 -> 2.0246953e-06 | O65: -868963.2 | P65: =D65+O65 -> -1105118.7 | Q65: =$Q$54*(C65-C64)*E65/E64 -> -1892183.3 | R65: =D65+Q65 -> -2128338.8
A66: USD | B66: LAM_STG_GRE | C66: 46274 | D66: 1125038.9 | E66: 4.0391641e+09 | F66: 4.1144542e+08 | G66: 14760495 | H66: =E66+F66 -> 4.4506096e+09 | I66: =(H66-H65-G66)/(H65+G66) -> 0.00025284702 | J66: =J65*(1+I66) -> 100.96119 | K66: =H66-H65-G66 -> 1125038.9 | L66: =K66-D66 -> -5.7828147e-06 | O66: -225965.62 | P66: =D66+O66 -> 899073.3 | Q66: =$Q$54*(C66-C65)*E66/E65 -> -474049.14 | R66: =D66+Q66 -> 650989.78
... A72: USD | B72: LAM_STG_GRE | C72: 46282 | D72: 620466.66 | E72: 3.9409529e+09 | F72: 6.3973973e+08 | G72: 1.0638206e+08 | H72: =E72+F72 -> 4.5806926e+09 | I72: =(H72-H71-G72)/(H71+G72) -> 0.00013547094 | J72: =J71*(1+I72) -> 101.18593 | K72: =H72-H71-G72 -> 620466.66 | L72: =K72-D72 -> -3.6577694e-06 | O72: -221081.48 | P72: =D72+O72 -> 399385.18 | Q72: =$Q$54*(C72-C71)*E72/E71 -> -452335.66 | R72: =D72+Q72 -> 168131
A73: USD | B73: LAM_STG_GRE | C73: 46283 | D73: 739137.04 | E73: 3.8684895e+09 | F73: 7.6263349e+08 | G73: 49691230 | H73: =E73+F73 -> 4.631123e+09 | I73: =(H73-H72-G73)/(H72+G73) -> 0.0001596276 | J73: =J72*(1+I73) -> 101.20208 | K73: =H73-H72-G73 -> 739137.04 | L73: =K73-D73 -> 6.146729e-07 | Q73: =$Q$54*(C73-C72)*E73/E72 -> -466892.13 | R73: =D73+Q73 -> 272244.91
A74: USD | B74: LAM_STG_GRE | C74: 46286 | D74: -894443.09 | E74: 3.8819588e+09 | F74: 7.7741478e+08 | G74: 29145044 | H74: =E74+F74 -> 4.6593736e+09 | I74: =(H74-H73-G74)/(H73+G74) -> -0.00019192954 | J74: =J73*(1+I74) -> 101.18266 | K74: =H74-H73-G74 -> -894443.09 | L74: =K74-D74 -> -2.0861626e-07 | Q74: =$Q$54*(C74-C73)*E74/E73 -> -1431881.7 | R74: =D74+Q74 -> -2326324.8
A75: USD | B75: LAM_STG_GRE | C75: 46287 | D75: -266260.98 | E75: 3.8907209e+09 | F75: 7.6841615e+08 | G75: 29794.392 | H75: =E75+F75 -> 4.6591371e+09 | I75: =(H75-H74-G75)/(H74+G75) -> -5.7144866e-05 | J75: =J74*(1+I75) -> 101.17688 | K75: =H75-H74-G75 -> -266260.98 | L75: =K75-D75 -> -1.590699e-06 | Q75: =$Q$54*(C75-C74)*E75/E74 -> -476711.4 | R75: =D75+Q75 -> -742972.38
A76: USD | B76: LAM_STG_GRE | C76: 46288 | D76: 4462602 | E76: 3.894438e+09 | F76: 7.3071418e+08 | G76: -38447556 | H76: =E76+F76 -> 4.6251521e+09 | I76: =(H76-H75-G76)/(H75+G76) -> 0.00096578703 | J76: =J75*(1+I76) -> 101.27459 | K76: =H76-H75-G76 -> 4462602 | L76: =K76-D76 -> 3.2931566e-06 | Q76: =$Q$54*(C76-C75)*E76/E75 -> -476092.21 | R76: =D76+Q76 -> 3986509.8
A77: USD | B77: LAM_STG_GRE | C77: 46289 | D77: 581295.25 | E77: 3.9557344e+09 | F77: 6.7001582e+08 | G77: 16741.257 | H77: =E77+F77 -> 4.6257502e+09 | I77: =(H77-H76-G77)/(H76+G77) -> 0.00012568087 | J77: =J76*(1+I77) -> 101.28732 | K77: =H77-H76-G77 -> 581295.25 | L77: =K77-D77 -> -1.9317959e-06 | Q77: =$Q$54*(C77-C76)*E77/E76 -> -483124.1 | R77: =D77+Q77 -> 98171.148
A78: USD | B78: LAM_STG_GRE | C78: 46290 | D78: -538065.85 | E78: 3.9553387e+09 | F78: 6.6989017e+08 | G78: 16743.052 | H78: =E78+F78 -> 4.6252289e+09 | I78: =(H78-H77-G78)/(H77+G78) -> -0.00011631927 | J78: =J77*(1+I78) -> 101.27554 | K78: =H78-H77-G78 -> -538065.85 | L78: =K78-D78 -> 5.3830445e-06 | Q78: =$Q$54*(C78-C77)*E78/E77 -> -475590.24 | R78: =D78+Q78 -> -1013656.1
A79: USD | B79: LAM_STG_GRE | C79: 46293 | D79: 1343010.3 | E79: 3.913892e+09 | F79: 6.5208626e+08 | G79: -60593624 | H79: =E79+F79 -> 4.5659782e+09 | I79: =(H79-H78-G79)/(H78+G79) -> 0.00029422073 | J79: =J78*(1+I79) -> 101.30534 | K79: =H79-H78-G79 -> 1343010.3 | L79: =K79-D79 -> -3.8146973e-06 | Q79: =$Q$54*(C79-C78)*E79/E78 -> -1411961.3 | R79: =D79+Q79 -> -68950.989
A80: USD | B80: LAM_STG_GRE | C80: 46294 | D80: -325657.04 | E80: 3.7307929e+09 | F80: 8.5219686e+08 | G80: 17337135 | H80: =E80+F80 -> 4.5829897e+09 | I80: =(H80-H79-G80)/(H79+G80) -> -7.1052723e-05 | J80: =J79*(1+I80) -> 101.29814 | K80: =H80-H79-G80 -> -325657.04 | L80: =K80-D80 -> -8.7171793e-07 | Q80: =$Q$54*(C80-C79)*E80/E79 -> -453386.59 | R80: =D80+Q80 -> -779043.63
A81: USD | B81: LAM_STG_GRE | C81: 46295 | D81: 576161.03 | E81: 3.7295137e+09 | F81: 1.0429973e+09 | G81: 1.889452e+08 | H81: =E81+F81 -> 4.7725111e+09 | I81: =(H81-H80-G81)/(H80+G81) -> 0.0001207395 | J81: =J80*(1+I81) -> 101.31037 | K81: =H81-H80-G81 -> 576161.03 | L81: =K81-D81 -> -2.0135194e-06 | Q81: =$Q$54*(C81-C80)*E81/E80 -> -475474.74 | R81: =D81+Q81 -> 100686.29
A82: USD | B82: LAM_STG_GRE | C82: 46296 | D82: -11099030 | E82: 3.7674531e+09 | F82: 1.0001515e+09 | G82: 6192533.4 | H82: =E82+F82 -> 4.7676046e+09 | I82: =(H82-H81-G82)/(H81+G82) -> -0.0023226028 | J82: =J81*(1+I82) -> 101.07507 | K82: =H82-H81-G82 -> -11099030 | L82: =K82-D82 -> 3.0249357e-06 | Q82: =$Q$54*(C82-C81)*E82/E81 -> -480476.35 | R82: =D82+Q82 -> -11579506
A83: USD | B83: LAM_STG_GRE | C83: 46297 | D83: 1070007.1 | E83: 3.7606486e+09 | F83: 1.0164854e+09 | G83: 8459348.5 | H83: =E83+F83 -> 4.7771339e+09 | I83: =(H83-H82-G83)/(H82+G83) -> 0.00022403535 | J83: =J82*(1+I83) -> 101.09771 | K83: =H83-H82-G83 -> 1070007.1 | L83: =K83-D83 -> -9.6485019e-07 | Q83: =$Q$54*(C83-C82)*E83/E82 -> -474778.74 | R83: =D83+Q83 -> 595228.39
...

Sheet Sheet4
A1: BOOK_CURRENCY_CODE | B1: Portfolio | C1: AS_OF_DATE | D1: Daily PL | E1: HOLDING_VALUE_RPT_CCY_AMT | F1: CASH_BALANCE_AMT | G1: EXTERNAL_CF_AMT | H1: NET_ASSET_VALUE_AMT | I1: Return | J1: Index | M1: Benchmark | N1: Benchmark Transfer | O1: Absolute Bench Inc | P1: Murex excess return | Q1: Corrected FTP cost | R1: Excess return after correction | S1: Bench Daily
A2: BRL | B2: POOL_LIQ_BRL | C2: 46294 | D2: 176529.39 | E2: 2.1520233e+08 | G2: 144348.23 | H2: =E2+F2 -> 2.1520233e+08
A3: BRL | B3: POOL_LIQ_BRL | C3: 46295 | D3: -260746.66 | E3: 2.1703288e+08 | F3: 633587.49 | G3: 231098.84 | H3: =E3+F3 -> 2.1766647e+08

Sheet Poool_liq_bRL

Sheet WTI
A1: BOOK_CURRENCY_CODE | B1: Portfolio | C1: AS_OF_DATE | D1: Daily PL | E1: HOLDING_VALUE_RPT_CCY_AMT | F1: CASH_BALANCE_AMT | G1: EXTERNAL_CF_AMT | H1: NET_ASSET_VALUE_AMT | I1: Return | J1: Index | M1: Benchmark | N1: Benchmark Transfer | O1: Absolute Bench Inc | P1: Murex excess return | Q1: Corrected FTP cost | R1: Excess return after correction | S1: Bench Daily
C2: 46203 | E2: 8.3498852e+08 | H2: 8.3498852e+08 | J2: 100 | S2: 0.00019119144
A3: USD | B3: LAM_STG_WTI | C3: 46204 | D3: 84384.44 | E3: 8.2558438e+08 | G3: =-(E2+D3-E3) -> -9488519.7 | H3: =E3+F3 -> 8.2558438e+08 | I3: =(H3-H2-G3)/(H2+G3) -> 0.00010222222 | J3: =J2*(1+I3) -> 100.01022 | K3: =H3-H2-G3 -> 84384.44 | L3: =K3-D3 -> -5.1470124e-08 | O3: =-(G3+H2)*S3 -> -90420.463 | P3: =O3+D3 -> -6036.0231 | Q3: =O3 -> -90420.463 | R3: =Q3+D3 -> -6036.0231 | S3: 0.00010953418
A4: USD | B4: LAM_STG_WTI | C4: 46205 | D4: 78843.05 | E4: 7.7746323e+08 | G4: =-(E3+D4-E4) -> -48200000 | H4: =E4+F4 -> 7.7746323e+08 | I4: =(H4-H3-G4)/(H3+G4) -> 0.00010142093 | J4: =J3*(1+I4) -> 100.02037 | K4: =H4-H3-G4 -> 78843.05 | L4: =K4-D4 -> 2.0620064e-08 | O4: =-(G4+H3)*S4 -> -84711.31 | P4: =O4+D4 -> -5868.2597 | Q4: =O4 -> -84711.31 | R4: =Q4+D4 -> -5868.2597 | S4: 0.00010896966
A5: USD | B5: LAM_STG_WTI | C5: 46206 | D5: 78749.34 | E5: 7.7754198e+08 | G5: =-(E4+D5-E5) -> 3.5762787e-07 | H5: =E5+F5 -> 7.7754198e+08 | I5: =(H5-H4-G5)/(H4+G5) -> 0.00010129012 | J5: =J4*(1+I5) -> 100.0305 | K5: =H5-H4-G5 -> 78749.34 | L5: =K5-D5 -> 4.8661605e-08 | O5: =-(G5+H4)*S5 -> -85140.405 | P5: =O5+D5 -> -6391.0647 | Q5: =O5 -> -85140.405 | R5: =Q5+D5 -> -6391.0647 | S5: 0.00010951052
A6: USD | B6: LAM_STG_WTI | C6: 46207 | D6: 79025.5 | E6: 7.77621e+08 | G6: =-(E5+D6-E6) -> -8.5830688e-06 | H6: =E6+F6 -> 7.77621e+08 | I6: =(H6-H5-G6)/(H5+G6) -> 0.00010163503 | J6: =J5*(1+I6) -> 100.04066 | K6: =H6-H5-G6 -> 79025.5 | L6: =K6-D6 -> 3.160676e-08 | O6: =-(G6+H5)*S6 -> -85139.49 | P6: =O6+D6 -> -6113.9904 | Q6: =O6 -> -85139.49 | R6: =Q6+D6 -> -6113.9904 | S6: 0.00010949826
A7: USD | B7: LAM_STG_WTI | C7: 46208 | D7: 79025.5 | E7: 7.7770003e+08 | G7: =-(E6+D7-E7) -> 3.5762787e-07 | H7: =E7+F7 -> 7.7770003e+08 | I7: =(H7-H6-G7)/(H6+G7) -> 0.0001016247 | J7: =J6*(1+I7) -> 100.05083 | K7: =H7-H6-G7 -> 79025.5 | L7: =K7-D7 -> 3.160676e-08 | O7: =-(G7+H6)*S7 -> -86181.846 | P7: =O7+D7 -> -7156.3461 | Q7: =O7 -> -86181.846 | R7: =Q7+D7 -> -7156.3461 | S7: 0.00011082757
A8: USD | B8: LAM_STG_WTI | C8: 46209 | D8: 68876.89 | E8: 6.8166718e+08 | G8: =-(E7+D8-E8) -> -96101727 | H8: =E8+F8 -> 6.8166718e+08 | I8: =(H8-H7-G8)/(H7+G8) -> 0.00010105203 | J8: =J7*(1+I8) -> 100.06094 | K8: =H8-H7-G8 -> 68876.89 | L8: =K8-D8 -> -5.2023097e-08 | O8: =-(G8+H7)*S8 -> -75829.826 | P8: =O8+D8 -> -6952.9357 | Q8: =O8 -> -75829.826 | R8: =Q8+D8 -> -6952.9357 | S8: 0.00011125296
A9: USD | B9: LAM_STG_WTI | C9: 46210 | D9: 61984.61 | E9: 6.1712916e+08 | G9: =-(E8+D9-E9) -> -64600000 | H9: =E9+F9 -> 6.1712916e+08 | I9: =(H9-H8-G9)/(H8+G9) -> 0.00010045034 | J9: =J8*(1+I9) -> 100.07099 | K9: =H9-H8-G9 -> 61984.61 | L9: =K9-D9 -> 2.1187589e-08 | O9: =-(G9+H8)*S9 -> -66619.813 | P9: =O9+D9 -> -4635.2034 | Q9: =O9 -> -66619.813 | R9: =Q9+D9 -> -4635.2034 | S9: 0.00010796201
A10: USD | B10: LAM_STG_WTI | C10: 46211 | D10: 62766.45 | E10: 6.2649193e+08 | G10: =-(E9+D10-E10) -> 9300000 | H10: =E10+F10 -> 6.2649193e+08 | I10: =(H10-H9-G10)/(H9+G10) -> 0.0001001972 | J10: =J9*(1+I10) -> 100.08102 | K10: =H10-H9-G10 -> 62766.45 | L10: =K10-D10 -> 2.7495844e-08 | O10: =-(G10+H9)*S10 -> -66141.051 | P10: =O10+D10 -> -3374.6014 | Q10: =O10 -> -66141.051 | R10: =Q10+D10 -> -3374.6014 | S10: 0.00010558425
A11: USD | B11: LAM_STG_WTI | C11: 46212 | D11: 47326.28 | E11: 4.8353925e+08 | G11: =-(E10+D11-E11) -> -143000000 | H11: =E11+F11 -> 4.8353925e+08 | I11: =(H11-H10-G11)/(H10+G11) -> 9.7884323e-05 | J11: =J10*(1+I11) -> 100.09081 | K11: =H11-H10-G11 -> 47326.28 | L11: =K11-D11 -> -2.7612259e-08 | O11: =-(G11+H10)*S11 -> -49190.013 | P11: =O11+D11 -> -1863.7334 | Q11: =O11 -> -49190.013 | R11: =Q11+D11 -> -1863.7334 | S11: 0.00010173906
A12: USD | B12: LAM_STG_WTI | C12: 46213 | D12: 41346.12 | E12: 4.291806e+08 | G12: =-(E11+D12-E12) -> -54400000 | H12: =E12+F12 -> 4.291806e+08 | I12: =(H12-H11-G12)/(H11+G12) -> 9.6346628e-05 | J12: =J11*(1+I12) -> 100.10046 | K12: =H12-H11-G12 -> 41346.12 | L12: =K12-D12 -> 1.1074007e-08 | O12: =-(G12+H11)*S12 -> -46825.3 | P12: =O12+D12 -> -5479.1798 | Q12: =O12 -> -46825.3 | R12: =Q12+D12 -> -5479.1798 | S12: 0.00010911446
A13: USD | B13: LAM_STG_WTI | C13: 46214 | D13: 42492.91 | E13: 4.2922309e+08 | G13: =-(E12+D13-E13) -> -5.9604645e-07 | H13: =E13+F13 -> 4.2922309e+08 | I13: =(H13-H12-G13)/(H12+G13) -> 9.9009391e-05 | J13: =J12*(1+I13) -> 100.11037 | K13: =H13-H12-G13 -> 42492.91 | L13: =K13-D13 -> -1.272565e-08 | O13: =-(G13+H12)*S13 -> -46184.386 | P13: =O13+D13 -> -3691.4763 | Q13: =O13 -> -46184.386 | R13: =Q13+D13 -> -3691.4763 | S13: 0.00010761061
A14: USD | B14: LAM_STG_WTI | C14: 46215 | D14: 42254.86 | E14: 4.2926535e+08 | G14: =-(E13+D14-E14) -> 1.1920929e-07 | H14: =E14+F14 -> 4.2926535e+08 | I14: =(H14-H13-G14)/(H13+G14) -> 9.8444983e-05 | J14: =J13*(1+I14) -> 100.12022 | K14: =H14-H13-G14 -> 42254.86 | L14: =K14-D14 -> 2.8769136e-08 | O14: =-(G14+H13)*S14 -> -45936.07 | P14: =O14+D14 -> -3681.2101 | Q14: =O14 -> -45936.07 | R14: =Q14+D14 -> -3681.2101 | S14: 0.00010702143
... A53: USD | B53: LAM_STG_WTI | C53: 46254 | D53: 99093.98 | E53: 9.9484167e+08 | G53: =-(E52+D53-E53) -> 2.3841858e-07 | H53: =E53+F53 -> 9.9484167e+08 | I53: =(H53-H52-G53)/(H52+G53) -> 9.9617713e-05 | J53: =J52*(1+I53) -> 100.49546 | K53: =H53-H52-G53 -> 99093.98 | L53: =K53-D53 -> 4.9330993e-08 | O53: =-(G53+H52)*S53 -> -111686.39 | P53: =O53+D53 -> -12592.408 | Q53: =O53 -> -111686.39 | R53: =Q53+D53 -> -12592.408 | S53: 0.00011227667
A54: USD | B54: LAM_STG_WTI | C54: 46255 | D54: =E54-E53 -> -602765.81 | E54: 9.942389e+08 | G54: =-(E53+D54-E54) -> 0 | H54: =E54+F54 -> 9.942389e+08 | I54: =(H54-H53-G54)/(H53+G54) -> -0.0006058912 | J54: =J53*(1+I54) -> 100.43457 | K54: =H54-H53-G54 -> -602765.81 | L54: =K54-D54 -> 0 | O54: =-(G54+H53)*$S$53 -> -111697.51 | P54: =O54+D54 -> -714463.33 | Q54: =O54 -> -111697.51 | R54: =Q54+D54 -> -714463.33 | S54: 1.0001123
A55: USD | B55: LAM_STG_WTI | C55: 46258 | D55: 285821.35 | E55: 1.0094393e+09 | G55: 14914576 | H55: =E55+F55 -> 1.0094393e+09 | I55: =(H55-H54-G55)/(H54+G55) -> 0.00028322882 | J55: =J54*(1+I55) -> 100.46302 | K55: =H55-H54-G55 -> 285821.35 | L55: =K55-D55 -> 1.1928496e-06 | O55: -127752.29 | P55: =D56+O55 -> -110659 | Q55: =$Q$54*(C55-C54)*E55/E54 -> -340215.6 | R55: =Q55+D55 -> -54394.249 | S55: =-O55/H55 -> 0.00012655767
A56: USD | B56: LAM_STG_WTI | C56: 46259 | D56: 17093.283 | E56: 1.1577542e+09 | G56: 1.4829777e+08 | H56: =E56+F56 -> 1.1577542e+09 | I56: =(H56-H55-G56)/(H55+G56) -> 1.4764391e-05 | J56: =J55*(1+I56) -> 100.4645 | K56: =H56-H55-G56 -> 17093.283 | L56: =K56-D56 -> 5.8413716e-06 | O56: -119225.67 | P56: =D57+O56 -> 43285.752 | Q56: =$Q$54*(C56-C55)*E56/E55 -> -128109 | R56: =Q56+D56 -> -111015.72 | S56: =-O56/H56 -> 0.00010298013
A57: USD | B57: LAM_STG_WTI | C57: 46260 | D57: 162511.43 | E57: 1.0748523e+09 | G57: -83064329 | H57: =E57+F57 -> 1.0748523e+09 | I57: =(H57-H56-G57)/(H56+G57) -> 0.00015121705 | J57: =J56*(1+I57) -> 100.4797 | K57: =H57-H56-G57 -> 162511.43 | L57: =K57-D57 -> 7.1444083e-07 | O57: -114195.51 | P57: =D58+O57 -> 10390.946 | Q57: =$Q$54*(C57-C56)*E57/E56 -> -103699.33 | R57: =Q57+D57 -> 58812.092 | S57: =-O57/H57 -> 0.00010624298
A58: USD | B58: LAM_STG_WTI | C58: 46261 | D58: 124586.46 | E58: 1.0429286e+09 | G58: -32048316 | H58: =E58+F58 -> 1.0429286e+09 | I58: =(H58-H57-G58)/(H57+G58) -> 0.00011947255 | J58: =J57*(1+I58) -> 100.4917 | K58: =H58-H57-G58 -> 124586.46 | L58: =K58-D58 -> 4.2919128e-06 | O58: -323085.36 | P58: =D59+O58 -> -198997.16 | Q58: =$Q$54*(C58-C57)*E58/E57 -> -108380.03 | R58: =Q58+D58 -> 16206.425 | S58: =-O58/H58 -> 0.00030978665
A59: USD | B59: LAM_STG_WTI | C59: 46262 | D59: 124088.2 | E59: 9.7842084e+08 | G59: -64631865 | H59: =E59+F59 -> 9.7842084e+08 | I59: =(H59-H58-G59)/(H58+G59) -> 0.00012684106 | J59: =J58*(1+I59) -> 100.50445 | K59: =H59-H58-G59 -> 124088.2 | L59: =K59-D59 -> -1.0490126e-05 | O59: -98909.595 | P59: =D60+O59 -> 251450.6 | Q59: =$Q$54*(C59-C58)*E59/E58 -> -104788.74 | R59: =Q59+D59 -> 19299.46 | S59: =-O59/H59 -> 0.00010109106
A60: USD | B60: LAM_STG_WTI | C60: 46265 | D60: 350360.2 | E60: 8.8894172e+08 | G60: -89829478 | H60: =E60+F60 -> 8.8894172e+08 | I60: =(H60-H59-G60)/(H59+G60) -> 0.0003942872 | J60: =J59*(1+I60) -> 100.54407 | K60: =H60-H59-G60 -> 350360.2 | L60: =K60-D60 -> 1.1886004e-07 | O60: -98009.246 | P60: =D61+O60 -> -8263.0432 | Q60: =$Q$54*(C60-C59)*E60/E59 -> -304447.46 | R60: =Q60+D60 -> 45912.738 | S60: =-O60/H60 -> 0.00011025385
A61: USD | B61: LAM_STG_WTI | C61: 46266 | D61: 89746.202 | E61: 8.7596329e+08 | G61: -13068182 | H61: =E61+F61 -> 8.7596329e+08 | I61: =(H61-H60-G61)/(H60+G61) -> 0.00010246479 | J61: =J60*(1+I61) -> 100.55438 | K61: =H61-H60-G61 -> 89746.202 | L61: =K61-D61 -> -8.3388295e-07 | O61: -86242.221 | P61: =D62+O61 -> 61561.591 | Q61: =$Q$54*(C61-C60)*E61/E60 -> -110066.74 | R61: =Q61+D61 -> -20320.542 | S61: =-O61/H61 -> 9.8454149e-05
A62: USD | B62: LAM_STG_WTI | C62: 46267 | D62: 147803.81 | E62: 7.8508969e+08 | G62: -91021407 | H62: =E62+F62 -> 7.8508969e+08 | I62: =(H62-H61-G62)/(H61+G62) -> 0.00018829905 | J62: =J61*(1+I62) -> 100.57331 | K62: =H62-H61-G62 -> 147803.81 | L62: =K62-D62 -> -3.578607e-07 | O62: -99890.067 | P62: =D63+O62 -> -93152.164 | Q62: =$Q$54*(C62-C61)*E62/E61 -> -100109.86 | R62: =Q62+D62 -> 47693.947 | S62: =-O62/H62 -> 0.00012723396
A63: USD | B63: LAM_STG_WTI | C63: 46268 | D63: 6737.9027 | E63: 9.0831759e+08 | G63: 1.2322117e+08 | H63: =E63+F63 -> 9.0831759e+08 | I63: =(H63-H62-G63)/(H62+G63) -> 7.4180581e-06 | J63: =J62*(1+I63) -> 100.57406 | K63: =H63-H62-G63 -> 6737.9027 | L63: =K63-D63 -> 3.5762787e-07 | O63: -399873.84 | P63: =D64+O63 -> -309915.77 | Q63: =$Q$54*(C63-C62)*E63/E62 -> -129229.59 | R63: =Q63+D63 -> -122491.69 | S63: =-O63/H63 -> 0.00044023571
A64: USD | B64: LAM_STG_WTI | C64: 46269 | D64: 89958.073 | E64: 9.0420222e+08 | G64: -4205328.5 | H64: =E64+F64 -> 9.0420222e+08 | I64: =(H64-H63-G64)/(H63+G64) -> 9.9498787e-05 | J64: =J63*(1+I64) -> 100.58406 | K64: =H64-H63-G64 -> 89958.073 | L64: =K64-D64 -> -3.5762787e-07 | O64: -106408.78 | P64: =D65+O64 -> 207612.63 | Q64: =$Q$54*(C64-C63)*E64/E63 -> -111191.44 | R64: =Q64+D64 -> -21233.366 | S64: =-O64/H64 -> 0.0001176825
A65: USD | B65: LAM_STG_WTI | C65: 46273 | D65: 314021.4 | E65: 9.7450346e+08 | G65: 69987217 | H65: =E65+F65 -> 9.7450346e+08 | I65: =(H65-H64-G65)/(H64+G65) -> 0.00032234121 | J65: =J64*(1+I65) -> 100.61649 | K65: =H65-H64-G65 -> 314021.4 | L65: =K65-D65 -> -1.1781231e-07 | O65: -108297.15 | P65: =D66+O65 -> -22814.316 | Q65: =$Q$54*(C65-C64)*E65/E64 -> -481527.74 | R65: =Q65+D65 -> -167506.34 | S65: =-O65/H65 -> 0.0001111306
A66: USD | B66: LAM_STG_WTI | C66: 46274 | D66: 85482.837 | E66: 9.8744887e+08 | G66: 12859926 | H66: =E66+F66 -> 9.8744887e+08 | I66: =(H66-H65-G66)/(H65+G66) -> 8.6576875e-05 | J66: =J65*(1+I66) -> 100.6252 | K66: =H66-H65-G66 -> 85482.837 | L66: =K66-D66 -> -2.7939677e-09 | O66: -102176.48 | P66: =D67+O66 -> 13632.474 | Q66: =$Q$54*(C66-C65)*E66/E65 -> -113181.32 | R66: =Q66+D66 -> -27698.479 | S66: =-O66/H66 -> 0.00010347521
... A72: USD | B72: LAM_STG_WTI | C72: 46282 | D72: 132811.06 | E72: 5.0580771e+08 | G72: -1.0392326e+08 | H72: =E72+F72 -> 5.0580771e+08 | I72: =(H72-H71-G72)/(H71+G72) -> 0.00026264118 | J72: =J71*(1+I72) -> 100.76135 | K72: =H72-H71-G72 -> 132811.06 | L72: =K72-D72 -> 8.3632767e-07 | O72: -3226.7994 | P72: =D73+O72 -> 172435.17 | Q72: =$Q$54*(C72-C71)*E72/E71 -> -92679.847 | R72: =Q72+D72 -> 40131.209 | S72: =-O72/H72 -> 6.3794983e-06
A73: USD | B73: LAM_STG_WTI | C73: 46283 | D73: 175661.97 | E73: 3.2134791e+08 | G73: -1.8463547e+08 | H73: =E73+F73 -> 3.2134791e+08 | I73: =(H73-H72-G73)/(H72+G73) -> 0.00054694008 | J73: =J72*(1+I73) -> 100.81646 | K73: =H73-H72-G73 -> 175661.97 | L73: =K73-D73 -> -3.608875e-07 | P73: =D74+O73 -> 119244.58 | Q73: =$Q$54*(C73-C72)*E73/E72 -> -70963.256 | R73: =Q73+D73 -> 104698.72
A74: USD | B74: LAM_STG_WTI | C74: 46286 | D74: 119244.58 | E74: 2.9550198e+08 | G74: -25965171 | H74: =E74+F74 -> 2.9550198e+08 | I74: =(H74-H73-G74)/(H73+G74) -> 0.00040369515 | J74: =J73*(1+I74) -> 100.85716 | K74: =H74-H73-G74 -> 119244.58 | L74: =K74-D74 -> 3.0267984e-07 | P74: =D75+O74 -> -21577.773 | Q74: =$Q$54*(C74-C73)*E74/E73 -> -308141.14 | R74: =Q74+D74 -> -188896.56
A75: USD | B75: LAM_STG_WTI | C75: 46287 | D75: -21577.773 | E75: 3.7354456e+08 | G75: 78064152 | H75: =E75+F75 -> 3.7354456e+08 | I75: =(H75-H74-G75)/(H74+G75) -> -5.7761587e-05 | J75: =J74*(1+I75) -> 100.85133 | K75: =H75-H74-G75 -> -21577.773 | L75: =K75-D75 -> -7.1991235e-07 | P75: =D76+O75 -> 120236.86 | Q75: =$Q$54*(C75-C74)*E75/E74 -> -141197.02 | R75: =Q75+D75 -> -162774.79
A76: USD | B76: LAM_STG_WTI | C76: 46288 | D76: 120236.86 | E76: 2.5063825e+08 | G76: -1.2302654e+08 | H76: =E76+F76 -> 2.5063825e+08 | I76: =(H76-H75-G76)/(H75+G76) -> 0.00047995295 | J76: =J75*(1+I76) -> 100.89974 | K76: =H76-H75-G76 -> 120236.86 | L76: =K76-D76 -> 5.6996942e-07 | P76: =D77+O76 -> 43490.099 | Q76: =$Q$54*(C76-C75)*E76/E75 -> -74945.997 | R76: =Q76+D76 -> 45290.861
A77: USD | B77: LAM_STG_WTI | C77: 46289 | D77: 43490.099 | E77: 2.2563118e+08 | G77: -25050562 | H77: =E77+F77 -> 2.2563118e+08 | I77: =(H77-H76-G77)/(H76+G77) -> 0.00019278578 | J77: =J76*(1+I77) -> 100.91919 | K77: =H77-H76-G77 -> 43490.099 | L77: =K77-D77 -> 2.9336661e-07 | P77: =D78+O77 -> 13256.417 | Q77: =$Q$54*(C77-C76)*E77/E76 -> -100553.05 | R77: =Q77+D77 -> -57062.956
A78: USD | B78: LAM_STG_WTI | C78: 46290 | D78: 13256.417 | E78: 2.4351464e+08 | G78: 17870203 | H78: =E78+F78 -> 2.4351464e+08 | I78: =(H78-H77-G78)/(H77+G78) -> 5.4440827e-05 | J78: =J77*(1+I78) -> 100.92468 | K78: =H78-H77-G78 -> 13256.417 | L78: =K78-D78 -> -1.4062971e-07 | P78: =D79+O78 -> 309954.93 | Q78: =$Q$54*(C78-C77)*E78/E77 -> -120550.63 | R78: =Q78+D78 -> -107294.21
A79: USD | B79: LAM_STG_WTI | C79: 46293 | D79: 309954.93 | E79: -89810317 | G79: -3.3363491e+08 | H79: =E79+F79 -> -89810317 | I79: =(H79-H78-G79)/(H78+G79) -> -0.0034393475 | J79: =J78*(1+I79) -> 100.57757 | K79: =H79-H78-G79 -> 309954.93 | L79: =K79-D79 -> -7.9115853e-07 | Q79: =$Q$54*(C79-C78)*E79/E78 -> 123585.04 | R79: =Q79+D79 -> 433539.98
A80: USD | B80: LAM_STG_WTI | C80: 46294 | D80: -10230.468 | E80: -89820547 | G80: 0 | H80: =E80+F80 -> -89820547 | I80: =(H80-H79-G80)/(H79+G80) -> 0.00011391195 | J80: =J79*(1+I80) -> 100.58903 | K80: =H80-H79-G80 -> -10230.468 | L80: =K80-D80 -> 1.7695129e-08 | Q80: =$Q$54*(C80-C79)*E80/E79 -> -111710.24 | R80: =Q80+D80 -> -121940.71
A81: USD | B81: LAM_STG_WTI | C81: 46295 | D81: -265845.25 | E81: 2.7989092e+08 | G81: 3.6997731e+08 | H81: =E81+F81 -> 2.7989092e+08 | I81: =(H81-H80-G81)/(H80+G81) -> -0.00094891605 | J81: =J80*(1+I81) -> 100.49358 | K81: =H81-H80-G81 -> -265845.25 | L81: =K81-D81 -> 2.9383227e-07 | Q81: =$Q$54*(C81-C80)*E81/E80 -> 348062 | R81: =Q81+D81 -> 82216.755
A82: USD | B82: LAM_STG_WTI | C82: 46296 | D82: -22983.508 | E82: 3.5070487e+08 | G82: 70836936 | H82: =E82+F82 -> 3.5070487e+08 | I82: =(H82-H81-G82)/(H81+G82) -> -6.553089e-05 | J82: =J81*(1+I82) -> 100.48699 | K82: =H82-H81-G82 -> -22983.508 | L82: =K82-D82 -> -3.6181882e-07 | Q82: =$Q$54*(C82-C81)*E82/E81 -> -139957.6 | R82: =Q82+D82 -> -162941.11
A83: USD | B83: LAM_STG_WTI | C83: 46297 | D83: 38324.702 | E83: 3.4577306e+08 | G83: -4970137.5 | H83: =E83+F83 -> 3.4577306e+08 | I83: =(H83-H82-G83)/(H82+G83) -> 0.00011085002 | J83: =J82*(1+I83) -> 100.49813 | K83: =H83-H82-G83 -> 38324.702 | L83: =K83-D83 -> 2.4074689e-07 | Q83: =$Q$54*(C83-C82)*E83/E82 -> -110126.76 | R83: =Q83+D83 -> -71802.057
...

Sheet SPUSA
A1: BOOK_CURRENCY_CODE | B1: Portfolio | C1: AS_OF_DATE | D1: Daily PL | E1: HOLDING_VALUE_RPT_CCY_AMT | F1: CASH_BALANCE_AMT | G1: EXTERNAL_CF_AMT | H1: NET_ASSET_VALUE_AMT | I1: Return | J1: Index | M1: Benchmark | N1: Benchmark Transfer | O1: Absolute Bench Inc | P1: Murex excess return | Q1: Corrected FTP cost | R1: Excess return after correction | S1: Bench Daily
C2: 46203 | E2: 4.8050873e+09 | F2: 6733906.5 | H2: =E2+F2 -> 4.8118212e+09 | J2: 100
A3: USD | B3: LAM_STG_SP_USA | C3: 46204 | D3: -211490.42 | E3: 4.8048758e+09 | F3: =F2 -> 6733906.5 | G3: =-(E2+D3-E3) -> 0 | H3: =E3+F3 -> 4.8116097e+09 | I3: =(H3-H2-G3)/(H2+G3) -> -4.3952261e-05 | J3: =J2*(1+I3) -> 99.995605 | K3: =H3-H2-G3 -> -211490.42 | L3: =K3-D3 -> -7.628114e-08 | O3: =-(H2+G3)*S3 -> -919979.02 | P3: =D3+O3 -> -1131469.4 | Q3: =O3 -> -919979.02 | R3: =D3+Q3 -> -1131469.4 | S3: 0.00019119144
A4: USD | B4: LAM_STG_SP_USA | C4: 46205 | D4: 232859.37 | E4: 4.8051087e+09 | F4: =F3 -> 6733906.5 | G4: =-(E3+D4-E4) -> 0 | H4: =E4+F4 -> 4.8118426e+09 | I4: =(H4-H3-G4)/(H3+G4) -> 4.8395315e-05 | J4: =J3*(1+I4) -> 100.00044 | K4: =H4-H3-G4 -> 232859.37 | L4: =K4-D4 -> -1.1443626e-07 | O4: =-(H3+G4)*S4 -> -527035.71 | P4: =D4+O4 -> -294176.34 | Q4: =O4 -> -527035.71 | R4: =D4+Q4 -> -294176.34 | S4: 0.00010953418
A5: USD | B5: LAM_STG_SP_USA | C5: 46206 | D5: 596914.32 | E5: 4.8057056e+09 | F5: =F4 -> 6733906.5 | G5: =-(E4+D5-E5) -> 0 | H5: =E5+F5 -> 4.8124395e+09 | I5: =(H5-H4-G5)/(H4+G5) -> 0.00012405109 | J5: =J4*(1+I5) -> 100.01285 | K5: =H5-H4-G5 -> 596914.32 | L5: =K5-D5 -> -3.0512456e-07 | O5: =-(H4+G5)*S5 -> -524344.84 | P5: =D5+O5 -> 72569.484 | Q5: =O5 -> -524344.84 | R5: =D5+Q5 -> 72569.484 | S5: 0.00010896966
A6: USD | B6: LAM_STG_SP_USA | C6: 46207 | D6: 597674.55 | E6: 4.8063033e+09 | F6: =F5 -> 6733906.5 | G6: =-(E5+D6-E6) -> 0 | H6: =E6+F6 -> 4.8130372e+09 | I6: =(H6-H5-G6)/(H5+G6) -> 0.00012419368 | J6: =J5*(1+I6) -> 100.02527 | K6: =H6-H5-G6 -> 597674.55 | L6: =K6-D6 -> 1.906883e-07 | O6: =-(H5+G6)*S6 -> -527012.77 | P6: =D6+O6 -> 70661.783 | Q6: =O6 -> -527012.77 | R6: =D6+Q6 -> 70661.783 | S6: 0.00010951052
A7: USD | B7: LAM_STG_SP_USA | C7: 46208 | D7: 597661.84 | E7: 4.8069009e+09 | F7: =F6 -> 6733906.5 | G7: =-(E6+D7-E7) -> 0 | H7: =E7+F7 -> 4.8136348e+09 | I7: =(H7-H6-G7)/(H6+G7) -> 0.00012417561 | J7: =J6*(1+I7) -> 100.03769 | K7: =H7-H6-G7 -> 597661.84 | L7: =K7-D7 -> 1.5262049e-07 | O7: =-(H6+G7)*S7 -> -527019.18 | P7: =D7+O7 -> 70642.663 | Q7: =O7 -> -527019.18 | R7: =D7+Q7 -> 70642.663 | S7: 0.00010949826
A8: USD | B8: LAM_STG_SP_USA | C8: 46209 | D8: 293216.71 | E8: 4.8071837e+09 | F8: =F7 -> 6733906.5 | G8: =-(E7+D8-E8) -> -10442.42 | H8: =E8+F8 -> 4.8139176e+09 | I8: =(H8-H7-G8)/(H7+G8) -> 6.0913916e-05 | J8: =J7*(1+I8) -> 100.04378 | K8: =H8-H7-G8 -> 293216.71 | L8: =K8-D8 -> 3.8126018e-08 | O8: =-(H7+G8)*S8 -> -533482.29 | P8: =D8+O8 -> -240265.58 | Q8: =O8 -> -533482.29 | R8: =D8+Q8 -> -240265.58 | S8: 0.00011082757
A9: USD | B9: LAM_STG_SP_USA | C9: 46210 | D9: 1340100.6 | E9: 4.8085238e+09 | F9: =F8 -> 6733906.5 | G9: =-(E8+D9-E9) -> 0 | H9: =E9+F9 -> 4.8152577e+09 | I9: =(H9-H8-G9)/(H8+G9) -> 0.00027838046 | J9: =J8*(1+I9) -> 100.07163 | K9: =H9-H8-G9 -> 1340100.6 | L9: =K9-D9 -> 1.5250407e-07 | O9: =-(H8+G9)*S9 -> -535562.56 | P9: =D9+O9 -> 804538.03 | Q9: =O9 -> -535562.56 | R9: =D9+Q9 -> 804538.03 | S9: 0.00011125296
A10: USD | B10: LAM_STG_SP_USA | C10: 46211 | D10: -786048.29 | E10: 4.8077378e+09 | F10: =F9 -> 6733906.5 | G10: =-(E9+D10-E10) -> 0 | H10: =E10+F10 -> 4.8144717e+09 | I10: =(H10-H9-G10)/(H9+G10) -> -0.00016324117 | J10: =J9*(1+I10) -> 100.0553 | K10: =H10-H9-G10 -> -786048.29 | L10: =K10-D10 -> 3.8184226e-08 | O10: =-(H9+G10)*S10 -> -519864.91 | P10: =D10+O10 -> -1305913.2 | Q10: =O10 -> -519864.91 | R10: =D10+Q10 -> -1305913.2 | S10: 0.00010796201
A11: USD | B11: LAM_STG_SP_USA | C11: 46212 | D11: 944816.04 | E11: 4.8086826e+09 | F11: =F10 -> 6733906.5 | G11: =-(E10+D11-E11) -> 0 | H11: =E11+F11 -> 4.8154165e+09 | I11: =(H11-H10-G11)/(H10+G11) -> 0.00019624501 | J11: =J10*(1+I11) -> 100.07493 | K11: =H11-H10-G11 -> 944816.04 | L11: =K11-D11 -> -3.8184226e-08 | O11: =-(H10+G11)*S11 -> -508332.37 | P11: =D11+O11 -> 436483.67 | Q11: =O11 -> -508332.37 | R11: =D11+Q11 -> 436483.67 | S11: 0.00010558425
A12: USD | B12: LAM_STG_SP_USA | C12: 46213 | D12: -91745.79 | E12: 4.8073642e+09 | F12: =F11 -> 6733906.5 | G12: =-(E11+D12-E12) -> -1226590.7 | H12: =E12+F12 -> 4.8140981e+09 | I12: =(H12-H11-G12)/(H11+G12) -> -1.9057368e-05 | J12: =J11*(1+I12) -> 100.07303 | K12: =H12-H11-G12 -> -91745.79 | L12: =K12-D12 -> 3.814057e-08 | O12: =-(H11+G12)*S12 -> -489791.14 | P12: =D12+O12 -> -581536.93 | Q12: =O12 -> -489791.14 | R12: =D12+Q12 -> -581536.93 | S12: 0.00010173906
A13: USD | B13: LAM_STG_SP_USA | C13: 46214 | D13: 605285.74 | E13: 4.8079695e+09 | F13: =F12 -> 6733906.5 | G13: =-(E12+D13-E13) -> -0.010000229 | H13: =E13+F13 -> 4.8147034e+09 | I13: =(H13-H12-G13)/(H12+G13) -> 0.00012573191 | J13: =J12*(1+I13) -> 100.08561 | K13: =H13-H12-G13 -> 605285.74 | L13: =K13-D13 -> -2.2887252e-07 | O13: =-(H12+G13)*S13 -> -525287.74 | P13: =D13+O13 -> 79998.001 | Q13: =O13 -> -525287.74 | R13: =D13+Q13 -> 79998.001 | S13: 0.00010911446
A14: USD | B14: LAM_STG_SP_USA | C14: 46215 | D14: 597856.84 | E14: 4.8085674e+09 | F14: =F13 -> 6733906.5 | G14: =-(E13+D14-E14) -> 0 | H14: =E14+F14 -> 4.8153013e+09 | I14: =(H14-H13-G14)/(H13+G14) -> 0.00012417314 | J14: =J13*(1+I14) -> 100.09804 | K14: =H14-H13-G14 -> 597856.84 | L14: =K14-D14 -> 1.5262049e-07 | O14: =-(H13+G14)*S14 -> -518113.17 | P14: =D14+O14 -> 79743.667 | Q14: =O14 -> -518113.17 | R14: =D14+Q14 -> 79743.667 | S14: 0.00010761061
... A53: USD | B53: LAM_STG_SP_USA | C53: 46254 | D53: 589513.59 | E53: 4.7833887e+09 | F53: =F52 -> 6733906.5 | G53: =-(E52+D53-E53) -> -63849564 | H53: =E53+F53 -> 4.7901226e+09 | I53: =(H53-H52-G53)/(H52+G53) -> 0.00012308373 | J53: =J52*(1+I53) -> 100.55505 | K53: =H53-H52-G53 -> 589513.59 | L53: =K53-D53 -> 1.5262049e-07 | O53: =-(H52+G53)*S53 -> -537752.84 | P53: =D53+O53 -> 51760.746 | Q53: =O53 -> -537752.84 | R53: =D53+Q53 -> 51760.746 | S53: 0.00011227667
A54: USD | B54: LAM_STG_SP_USA | C54: 46255 | D54: 2400.2185 | E54: 4.7806231e+09 | F54: 9501906.9 | H54: =E54+F54 -> 4.790125e+09 | I54: =(H54-H53-G54)/(H53+G54) -> 5.0107664e-07 | J54: =J53*(1+I54) -> 100.5551 | K54: =H54-H53-G54 -> 2400.2185 | L54: =K54-D54 -> 5.8060978e-06 | O54: =-(H53+G54)*S54 -> -537819.03 | P54: =D54+O54 -> -535418.81 | Q54: =O54 -> -537819.03 | R54: =D54+Q54 -> -535418.81 | S54: =S53 -> 0.00011227667
A55: USD | B55: LAM_STG_SP_USA | C55: 46258 | D55: 1800417.8 | E55: 4.4988044e+09 | F55: 2.9982088e+08 | G55: 6699889.5 | H55: =E55+F55 -> 4.7986253e+09 | I55: =(H55-H54-G55)/(H54+G55) -> 0.00037533532 | J55: =J54*(1+I55) -> 100.59284 | K55: =H55-H54-G55 -> 1800417.8 | L55: =K55-D55 -> 0.0003054454 | O55: -2911258.2 | P55: =D55+O55 -> -1110840.4 | Q55: =$Q$54*(C55-C54)*E55/E54 -> -1518343.5 | R55: =D55+Q55 -> 282074.3
A56: USD | B56: LAM_STG_SP_USA | C56: 46259 | D56: 448295.7 | E56: 4.7821965e+09 | F56: 1.6969088e+08 | G56: 1.5281377e+08 | H56: =E56+F56 -> 4.9518874e+09 | I56: =(H56-H55-G56)/(H55+G56) -> 9.0538466e-05 | J56: =J55*(1+I56) -> 100.60195 | K56: =H56-H55-G56 -> 448295.7 | L56: =K56-D56 -> -1.9057188e-07 | O56: -1024054.7 | P56: =D56+O56 -> -575758.96 | Q56: =$Q$54*(C56-C55)*E56/E55 -> -571697.73 | R56: =D56+Q56 -> -123402.04
A57: USD | B57: LAM_STG_SP_USA | C57: 46260 | D57: 1368644.1 | E57: 4.7835651e+09 | F57: 11723279 | G57: -1.579676e+08 | H57: =E57+F57 -> 4.7952884e+09 | I57: =(H57-H56-G57)/(H56+G57) -> 0.00028549583 | J57: =J56*(1+I57) -> 100.63067 | K57: =H57-H56-G57 -> 1368644.1 | L57: =K57-D57 -> -1.950888e-06 | O57: -1012622.6 | P57: =D57+O57 -> 356021.5 | Q57: =$Q$54*(C57-C56)*E57/E56 -> -537972.95 | R57: =D57+Q57 -> 830671.13
A58: USD | B58: LAM_STG_SP_USA | C58: 46261 | D58: 197239.02 | E58: 4.8534455e+09 | F58: -55341690 | G58: 2618175 | H58: =E58+F58 -> 4.7981038e+09 | I58: =(H58-H57-G58)/(H57+G58) -> 4.110939e-05 | J58: =J57*(1+I58) -> 100.63481 | K58: =H58-H57-G58 -> 197239.02 | L58: =K58-D58 -> 4.9270457e-06 | O58: -1023598.3 | P58: =D58+O58 -> -826359.25 | Q58: =$Q$54*(C58-C57)*E58/E57 -> -545675.72 | R58: =D58+Q58 -> -348436.71
A59: USD | B59: LAM_STG_SP_USA | C59: 46262 | D59: -916775.91 | E59: 4.8525358e+09 | F59: -1.1960429e+08 | G59: -64255556 | H59: =E59+F59 -> 4.7329315e+09 | I59: =(H59-H58-G59)/(H58+G59) -> -0.00019366398 | J59: =J58*(1+I59) -> 100.61532 | K59: =H59-H58-G59 -> -916775.91 | L59: =K59-D59 -> 2.3173634e-06 | O59: -1191349.7 | P59: =D59+O59 -> -2108125.6 | Q59: =$Q$54*(C59-C58)*E59/E58 -> -537718.22 | R59: =D59+Q59 -> -1454494.1
A60: USD | B60: LAM_STG_SP_USA | C60: 46265 | D60: 1827765.3 | E60: 4.8804117e+09 | F60: -1.4540261e+08 | G60: 249846.98 | H60: =E60+F60 -> 4.7350091e+09 | I60: =(H60-H59-G60)/(H59+G60) -> 0.00038615999 | J60: =J59*(1+I60) -> 100.65417 | K60: =H60-H59-G60 -> 1827765.3 | L60: =K60-D60 -> -6.0221646e-06 | O60: -2932359.3 | P60: =D60+O60 -> -1104594 | Q60: =$Q$54*(C60-C59)*E60/E59 -> -1622725.8 | R60: =D60+Q60 -> 205039.47
A61: USD | B61: LAM_STG_SP_USA | C61: 46266 | D61: 651592.83 | E61: 4.881066e+09 | F61: -1.6098125e+08 | G61: -15575995 | H61: =E61+F61 -> 4.7200847e+09 | I61: =(H61-H60-G61)/(H60+G61) -> 0.00013806591 | J61: =J60*(1+I61) -> 100.66807 | K61: =H61-H60-G61 -> 651592.83 | L61: =K61-D61 -> 4.2784959e-06 | O61: -1041495.2 | P61: =D61+O61 -> -389902.38 | Q61: =$Q$54*(C61-C60)*E61/E60 -> -537891.13 | R61: =D61+Q61 -> 113701.7
A62: USD | B62: LAM_STG_SP_USA | C62: 46267 | D62: 806285.41 | E62: 4.8818722e+09 | F62: -1.6089779e+08 | G62: 83455.363 | H62: =E62+F62 -> 4.7209744e+09 | I62: =(H62-H61-G62)/(H61+G62) -> 0.00017081709 | J62: =J61*(1+I62) -> 100.68526 | K62: =H62-H61-G62 -> 806285.41 | L62: =K62-D62 -> 2.2217864e-06 | O62: -1037983.6 | P62: =D62+O62 -> -231698.16 | Q62: =$Q$54*(C62-C61)*E62/E61 -> -537907.87 | R62: =D62+Q62 -> 268377.54
A63: USD | B63: LAM_STG_SP_USA | C63: 46268 | D63: 2041570 | E63: 4.8839138e+09 | F63: -1.6081433e+08 | G63: 83463.855 | H63: =E63+F63 -> 4.7230995e+09 | I63: =(H63-H62-G63)/(H62+G63) -> 0.0004324391 | J63: =J62*(1+I63) -> 100.7288 | K63: =H63-H62-G63 -> 2041570 | L63: =K63-D63 -> -5.1916577e-06 | O63: -1035481.4 | P63: =D63+O63 -> 1006088.7 | Q63: =$Q$54*(C63-C62)*E63/E62 -> -538043.95 | R63: =D63+Q63 -> 1503526.1
A64: USD | B64: LAM_STG_SP_USA | C64: 46269 | D64: 19414.347 | E64: 4.88141e+09 | F64: -1.5820761e+08 | G64: 83472.311 | H64: =E64+F64 -> 4.7232024e+09 | I64: =(H64-H63-G64)/(H63+G64) -> 4.1104373e-06 | J64: =J63*(1+I64) -> 100.72922 | K64: =H64-H63-G64 -> 19414.347 | L64: =K64-D64 -> -1.0014337e-06 | O64: -1290093.8 | P64: =D64+O64 -> -1270679.5 | Q64: =$Q$54*(C64-C63)*E64/E63 -> -537543.31 | R64: =D64+Q64 -> -518128.96
A65: USD | B65: LAM_STG_SP_USA | C65: 46273 | D65: 1578585.2 | E65: 4.8829875e+09 | F65: -1.5787266e+08 | G65: 333923.21 | H65: =E65+F65 -> 4.7251149e+09 | I65: =(H65-H64-G65)/(H64+G65) -> 0.00033419564 | J65: =J64*(1+I65) -> 100.76288 | K65: =H65-H64-G65 -> 1578585.2 | L65: =K65-D65 -> -5.6810677e-07 | O65: -3890870.3 | P65: =D65+O65 -> -2312285.1 | Q65: =$Q$54*(C65-C64)*E65/E64 -> -2151971.4 | R65: =D65+Q65 -> -573386.15
A66: USD | B66: LAM_STG_SP_USA | C66: 46274 | D66: 578692.08 | E66: 4.8979531e+09 | F66: -1.7217604e+08 | G66: 83514.659 | H66: =E66+F66 -> 4.7257771e+09 | I66: =(H66-H65-G66)/(H65+G66) -> 0.00012246937 | J66: =J65*(1+I66) -> 100.77522 | K66: =H66-H65-G66 -> 578692.08 | L66: =K66-D66 -> -1.1527445e-06 | O66: -1033501.8 | P66: =D66+O66 -> -454809.73 | Q66: =$Q$54*(C66-C65)*E66/E65 -> -539467.36 | R66: =D66+Q66 -> 39224.719
... A72: USD | B72: LAM_STG_SP_USA | C72: 46282 | D72: 3387316.7 | E72: 4.8432459e+09 | F72: -97710176 | G72: -308004.88 | H72: =E72+F72 -> 4.7455358e+09 | I72: =(H72-H71-G72)/(H71+G72) -> 0.00071430001 | J72: =J71*(1+I72) -> 100.89784 | K72: =H72-H71-G72 -> 3387316.7 | L72: =K72-D72 -> -3.3969991e-06 | O72: -1027612.7 | P72: =D72+O72 -> 2359704 | Q72: =$Q$54*(C72-C71)*E72/E71 -> -538217.63 | R72: =D72+Q72 -> 2849099.1
A73: USD | B73: LAM_STG_SP_USA | C73: 46283 | D73: 262259.02 | E73: 4.8482446e+09 | F73: -86036136 | G73: 16410404 | H73: =E73+F73 -> 4.7622084e+09 | I73: =(H73-H72-G73)/(H72+G73) -> 5.5073916e-05 | J73: =J72*(1+I73) -> 100.9034 | K73: =H73-H72-G73 -> 262259.02 | L73: =K73-D73 -> -4.5149936e-06 | Q73: =$Q$54*(C73-C72)*E73/E72 -> -538374.11 | R73: =D73+Q73 -> -276115.08
A74: USD | B74: LAM_STG_SP_USA | C74: 46286 | D74: 1481463 | E74: 4.868917e+09 | F74: -1.6097923e+08 | G74: -55752107 | H74: =E74+F74 -> 4.7079378e+09 | I74: =(H74-H73-G74)/(H73+G74) -> 0.0003147725 | J74: =J73*(1+I74) -> 100.93516 | K74: =H74-H73-G74 -> 1481463 | L74: =K74-D74 -> -4.2752363e-06 | Q74: =$Q$54*(C74-C73)*E74/E73 -> -1620336.7 | R74: =D74+Q74 -> -138873.69
A75: USD | B75: LAM_STG_SP_USA | C75: 46287 | D75: -273590.98 | E75: 4.8601211e+09 | F75: -1.1959119e+08 | G75: 32865731 | H75: =E75+F75 -> 4.7405299e+09 | I75: =(H75-H74-G75)/(H74+G75) -> -5.7709833e-05 | J75: =J74*(1+I75) -> 100.92933 | K75: =H75-H74-G75 -> -273590.98 | L75: =K75-D75 -> 8.1077451e-07 | Q75: =$Q$54*(C75-C74)*E75/E74 -> -536847.44 | R75: =D75+Q75 -> -810438.42
A76: USD | B76: LAM_STG_SP_USA | C76: 46288 | D76: 1716978.5 | E76: 4.8622727e+09 | F76: -1.3121182e+08 | G76: -11186035 | H76: =E76+F76 -> 4.7310609e+09 | I76: =(H76-H75-G76)/(H75+G76) -> 0.00036304793 | J76: =J75*(1+I76) -> 100.96598 | K76: =H76-H75-G76 -> 1716978.5 | L76: =K76-D76 -> 6.0114544e-06 | Q76: =$Q$54*(C76-C75)*E76/E75 -> -538057.12 | R76: =D76+Q76 -> 1178921.4
A77: USD | B77: LAM_STG_SP_USA | C77: 46289 | D77: -388671.59 | E77: 4.8618831e+09 | F77: -1.3112723e+08 | G77: 83686.983 | H77: =E77+F77 -> 4.7307559e+09 | I77: =(H77-H76-G77)/(H76+G77) -> -8.2151705e-05 | J77: =J76*(1+I77) -> 100.95768 | K77: =H77-H76-G77 -> -388671.59 | L77: =K77-D77 -> -3.6972342e-06 | Q77: =$Q$54*(C77-C76)*E77/E76 -> -537775.94 | R77: =D77+Q77 -> -926447.53
A78: USD | B78: LAM_STG_SP_USA | C78: 46290 | D78: -311993.07 | E78: 4.8614436e+09 | F78: -1.1211799e+08 | G78: 18881679 | H78: =E78+F78 -> 4.7493256e+09 | I78: =(H78-H77-G78)/(H77+G78) -> -6.5687764e-05 | J78: =J77*(1+I78) -> 100.95105 | K78: =H78-H77-G78 -> -311993.07 | L78: =K78-D78 -> 1.2867386e-06 | Q78: =$Q$54*(C78-C77)*E78/E77 -> -537770.41 | R78: =D78+Q78 -> -849763.48
A79: USD | B79: LAM_STG_SP_USA | C79: 46293 | D79: 1324938.3 | E79: 4.8627685e+09 | F79: -1.1123133e+08 | G79: 886665.5 | H79: =E79+F79 -> 4.7515372e+09 | I79: =(H79-H78-G79)/(H78+G79) -> 0.00027892192 | J79: =J78*(1+I79) -> 100.97921 | K79: =H79-H78-G79 -> 1324938.3 | L79: =K79-D79 -> 1.6223639e-06 | Q79: =$Q$54*(C79-C78)*E79/E78 -> -1613896.8 | R79: =D79+Q79 -> -288958.52
A80: USD | B80: LAM_STG_SP_USA | C80: 46294 | D80: 1247421.1 | E80: 4.8640159e+09 | F80: -1.1114777e+08 | G80: 83559.404 | H80: =E80+F80 -> 4.7528681e+09 | I80: =(H80-H79-G80)/(H79+G80) -> 0.00026252538 | J80: =J79*(1+I80) -> 101.00572 | K80: =H80-H79-G80 -> 1247421.1 | L80: =K80-D80 -> 2.3588073e-06 | Q80: =$Q$54*(C80-C79)*E80/E79 -> -537957 | R80: =D80+Q80 -> 709464.06
A81: USD | B81: LAM_STG_SP_USA | C81: 46295 | D81: -800066.77 | E81: 4.8632247e+09 | F81: -1.1107303e+08 | G81: 83568.462 | H81: =E81+F81 -> 4.7521516e+09 | I81: =(H81-H80-G81)/(H80+G81) -> -0.00016833051 | J81: =J80*(1+I81) -> 100.98871 | K81: =H81-H80-G81 -> -800066.77 | L81: =K81-D81 -> -4.5634806e-08 | Q81: =$Q$54*(C81-C80)*E81/E80 -> -537731.54 | R81: =D81+Q81 -> -1337798.3
A82: USD | B82: LAM_STG_SP_USA | C82: 46296 | D82: 1522347.6 | E82: 4.8722588e+09 | F82: -89063308 | G82: 29521483 | H82: =E82+F82 -> 4.7831955e+09 | I82: =(H82-H81-G82)/(H81+G82) -> 0.00031837132 | J82: =J81*(1+I82) -> 101.02087 | K82: =H82-H81-G82 -> 1522347.6 | L82: =K82-D82 -> 8.889474e-07 | Q82: =$Q$54*(C82-C81)*E82/E81 -> -538818.11 | R82: =D82+Q82 -> 983529.49
A83: USD | B83: LAM_STG_SP_USA | C83: 46297 | D83: 613263.55 | E83: 4.8728733e+09 | F83: -1.0033027e+08 | G83: -11265731 | H83: =E83+F83 -> 4.772543e+09 | I83: =(H83-H82-G83)/(H82+G83) -> 0.00012851479 | J83: =J82*(1+I83) -> 101.03385 | K83: =H83-H82-G83 -> 613263.55 | L83: =K83-D83 -> -3.6405399e-06 | Q83: =$Q$54*(C83-C82)*E83/E82 -> -537886.86 | R83: =D83+Q83 -> 75376.686
...

Sheet SPINT
A1: BOOK_CURRENCY_CODE | B1: Portfolio | C1: AS_OF_DATE | D1: Daily PL | E1: HOLDING_VALUE_RPT_CCY_AMT | F1: CASH_BALANCE_AMT | G1: EXTERNAL_CF_AMT | H1: NET_ASSET_VALUE_AMT | I1: Return | J1: Index | M1: Benchmark | N1: Benchmark Transfer | O1: Absolute Bench Inc | P1: Murex excess return | Q1: Corrected FTP cost | R1: Excess return after correction | S1: Bench Daily
C2: 46203 | E2: 1.8751855e+09 | F2: 4979480.8 | H2: =E2+F2 -> 1.880165e+09 | J2: 100
A3: USD | B3: LAM_STG_SP_INT | C3: 46204 | D3: 224727.79 | E3: 1.8754102e+09 | F3: =F2 -> 4979480.8 | G3: =-(E2+D3-E3) -> 0 | H3: =E3+F3 -> 1.8803897e+09 | I3: =(H3-H2-G3)/(H2+G3) -> 0.00011952557 | J3: =J2*(1+I3) -> 100.01195 | K3: =H3-H2-G3 -> 224727.79 | L3: =K3-D3 -> -3.8155122e-08 | O3: =-(H2+G3)*S3 -> -359471.44 | P3: =D3+O3 -> -134743.65 | Q3: =O3 -> -359471.44 | R3: =D3+Q3 -> -134743.65 | S3: 0.00019119144
A4: USD | B4: LAM_STG_SP_INT | C4: 46205 | D4: 350329.63 | E4: 1.9269501e+09 | F4: =F3 -> 4979480.8 | G4: =-(E3+D4-E4) -> 51189615 | H4: =E4+F4 -> 1.9319296e+09 | I4: =(H4-H3-G4)/(H3+G4) -> 0.00018136953 | J4: =J3*(1+I4) -> 100.03009 | K4: =H4-H3-G4 -> 350329.63 | L4: =K4-D4 -> 1.1443626e-07 | O4: =-(H3+G4)*S4 -> -211573.95 | P4: =D4+O4 -> 138755.68 | Q4: =O4 -> -211573.95 | R4: =D4+Q4 -> 138755.68 | S4: 0.00010953418
A5: USD | B5: LAM_STG_SP_INT | C5: 46206 | D5: 259590.73 | E5: 1.927243e+09 | F5: =F4 -> 4979480.8 | G5: =-(E4+D5-E5) -> 33265.05 | H5: =E5+F5 -> 1.9322225e+09 | I5: =(H5-H4-G5)/(H4+G5) -> 0.00013436631 | J5: =J4*(1+I5) -> 100.04353 | K5: =H5-H4-G5 -> 259590.73 | L5: =K5-D5 -> 1.9063009e-08 | O5: =-(H4+G5)*S5 -> -210525.33 | P5: =D5+O5 -> 49065.397 | Q5: =O5 -> -210525.33 | R5: =D5+Q5 -> 49065.397 | S5: 0.00010896966
A6: USD | B6: LAM_STG_SP_INT | C6: 46207 | D6: 375433.51 | E6: 1.9276184e+09 | F6: =F5 -> 4979480.8 | G6: =-(E5+D6-E6) -> 0 | H6: =E6+F6 -> 1.9325979e+09 | I6: =(H6-H5-G6)/(H5+G6) -> 0.00019430139 | J6: =J5*(1+I6) -> 100.06297 | K6: =H6-H5-G6 -> 375433.51 | L6: =K6-D6 -> -9.5460564e-09 | O6: =-(H5+G6)*S6 -> -211598.69 | P6: =D6+O6 -> 163834.82 | Q6: =O6 -> -211598.69 | R6: =D6+Q6 -> 163834.82 | S6: 0.00010951052
A7: USD | B7: LAM_STG_SP_INT | C7: 46208 | D7: 222999.58 | E7: 1.9278414e+09 | F7: =F6 -> 4979480.8 | G7: =-(E6+D7-E7) -> 0 | H7: =E7+F7 -> 1.9328209e+09 | I7: =(H7-H6-G7)/(H6+G7) -> 0.0001153885 | J7: =J6*(1+I7) -> 100.07452 | K7: =H7-H6-G7 -> 222999.58 | L7: =K7-D7 -> -7.628114e-08 | O7: =-(H6+G7)*S7 -> -211616.1 | P7: =D7+O7 -> 11383.479 | Q7: =O7 -> -211616.1 | R7: =D7+Q7 -> 11383.479 | S7: 0.00010949826
A8: USD | B8: LAM_STG_SP_INT | C8: 46209 | D8: 69577.91 | E8: 1.9783032e+09 | F8: =F7 -> 4979480.8 | G8: =-(E7+D8-E8) -> 50392196 | H8: =E8+F8 -> 1.9832827e+09 | I8: =(H8-H7-G8)/(H7+G8) -> 3.5083426e-05 | J8: =J7*(1+I8) -> 100.07803 | K8: =H8-H7-G8 -> 69577.91 | L8: =K8-D8 -> 8.5827196e-08 | O8: =-(H7+G8)*S8 -> -219794.69 | P8: =D8+O8 -> -150216.78 | Q8: =O8 -> -219794.69 | R8: =D8+Q8 -> -150216.78 | S8: 0.00011082757
A9: USD | B9: LAM_STG_SP_INT | C9: 46210 | D9: 243104.35 | E9: 1.9785463e+09 | F9: =F8 -> 4979480.8 | G9: =-(E8+D9-E9) -> 21.63 | H9: =E9+F9 -> 1.9835258e+09 | I9: =(H9-H8-G9)/(H8+G9) -> 0.00012257675 | J9: =J8*(1+I9) -> 100.0903 | K9: =H9-H8-G9 -> 243104.35 | L9: =K9-D9 -> -9.5373252e-08 | O9: =-(H8+G9)*S9 -> -220646.06 | P9: =D9+O9 -> 22458.286 | Q9: =O9 -> -220646.06 | R9: =D9+Q9 -> 22458.286 | S9: 0.00011125296
A10: USD | B10: LAM_STG_SP_INT | C10: 46211 | D10: 263752.67 | E10: 1.9779197e+09 | F10: =F9 -> 4979480.8 | G10: =-(E9+D10-E10) -> -890383.03 | H10: =E10+F10 -> 1.9828992e+09 | I10: =(H10-H9-G10)/(H9+G10) -> 0.00013303135 | J10: =J9*(1+I10) -> 100.10361 | K10: =H10-H9-G10 -> 263752.67 | L10: =K10-D10 -> 7.6310243e-08 | O10: =-(H9+G10)*S10 -> -214049.31 | P10: =D10+O10 -> 49703.362 | Q10: =O10 -> -214049.31 | R10: =D10+Q10 -> 49703.362 | S10: 0.00010796201
A11: USD | B11: LAM_STG_SP_INT | C11: 46212 | D11: 250836.59 | E11: 2.0199345e+09 | F11: =F10 -> 4979480.8 | G11: =-(E10+D11-E11) -> 41763995 | H11: =E11+F11 -> 2.024914e+09 | I11: =(H11-H10-G11)/(H10+G11) -> 0.00012389053 | J11: =J10*(1+I11) -> 100.11601 | K11: =H11-H10-G11 -> 250836.59 | L11: =K11-D11 -> -8.5827196e-08 | O11: =-(H10+G11)*S11 -> -213772.54 | P11: =D11+O11 -> 37064.053 | Q11: =O11 -> -213772.54 | R11: =D11+Q11 -> 37064.053 | S11: 0.00010558425
A12: USD | B12: LAM_STG_SP_INT | C12: 46213 | D12: 267522.07 | E12: 1.9811751e+09 | F12: =F11 -> 4979480.8 | G12: =-(E11+D12-E12) -> -39026961 | H12: =E12+F12 -> 1.9861546e+09 | I12: =(H12-H11-G12)/(H11+G12) -> 0.00013471162 | J12: =J11*(1+I12) -> 100.1295 | K12: =H12-H11-G12 -> 267522.07 | L12: =K12-D12 -> -6.6764187e-08 | O12: =-(H11+G12)*S12 -> -202042.28 | P12: =D12+O12 -> 65479.792 | Q12: =O12 -> -202042.28 | R12: =D12+Q12 -> 65479.792 | S12: 0.00010173906
A13: USD | B13: LAM_STG_SP_INT | C13: 46214 | D13: 237006.44 | E13: 1.9814121e+09 | F13: =F12 -> 4979480.8 | G13: =-(E12+D13-E13) -> 0 | H13: =E13+F13 -> 1.9863916e+09 | I13: =(H13-H12-G13)/(H12+G13) -> 0.0001193293 | J13: =J12*(1+I13) -> 100.14145 | K13: =H13-H12-G13 -> 237006.44 | L13: =K13-D13 -> 5.7218131e-08 | O13: =-(H12+G13)*S13 -> -216718.19 | P13: =D13+O13 -> 20288.248 | Q13: =O13 -> -216718.19 | R13: =D13+Q13 -> 20288.248 | S13: 0.00010911446
A14: USD | B14: LAM_STG_SP_INT | C14: 46215 | D14: 263379.29 | E14: 1.9816755e+09 | F14: =F13 -> 4979480.8 | G14: =-(E13+D14-E14) -> 0 | H14: =E14+F14 -> 1.986655e+09 | I14: =(H14-H13-G14)/(H13+G14) -> 0.00013259183 | J14: =J13*(1+I14) -> 100.15473 | K14: =H14-H13-G14 -> 263379.29 | L14: =K14-D14 -> -3.8126018e-08 | O14: =-(H13+G14)*S14 -> -213756.81 | P14: =D14+O14 -> 49622.48 | Q14: =O14 -> -213756.81 | R14: =D14+Q14 -> 49622.48 | S14: 0.00010761061
... A53: USD | B53: LAM_STG_SP_INT | C53: 46254 | D53: 213836.87 | E53: 2.0699642e+09 | F53: =F52 -> 4979480.8 | G53: =-(E52+D53-E53) -> -8506793.6 | H53: =E53+F53 -> 2.0749436e+09 | I53: =(H53-H52-G53)/(H52+G53) -> 0.00010306733 | J53: =J52*(1+I53) -> 100.60278 | K53: =H53-H52-G53 -> 213836.87 | L53: =K53-D53 -> -1.1443626e-07 | O53: =-(H52+G53)*S53 -> -232943.76 | P53: =D53+O53 -> -19106.891 | Q53: =O53 -> -232943.76 | R53: =D53+Q53 -> -19106.891 | S53: 0.00011227667
A54: USD | B54: LAM_STG_SP_INT | C54: 46255 | D54: 1355009.9 | E54: 2.1012347e+09 | F54: -24936019 | H54: =E54+F54 -> 2.0762986e+09 | I54: =(H54-H53-G54)/(H53+G54) -> 0.00065303455 | J54: =J53*(1+I54) -> 100.66847 | K54: =H54-H53-G54 -> 1355009.9 | L54: =K54-D54 -> 4.3541659e-06 | O54: =-(H53+G54)*S54 -> -232967.77 | P54: =D54+O54 -> 1122042.1 | Q54: =O54 -> -232967.77 | R54: =D54+Q54 -> 1122042.1 | S54: 0.00011227667
A55: USD | B55: LAM_STG_SP_INT | C55: 46258 | D55: 662716.21 | E55: 2.1021341e+09 | F55: -17323785 | G55: 7848982.9 | H55: =E55+F55 -> 2.0848103e+09 | I55: =(H55-H54-G55)/(H54+G55) -> 0.0003179795 | J55: =J54*(1+I55) -> 100.70048 | K55: =H55-H54-G55 -> 662716.21 | L55: =K55-D55 -> 1.5506521e-06 | O55: -8094.1062 | P55: =D55+O55 -> 654622.11 | Q55: =$Q$54*(C55-C54)*E55/E54 -> -699202.49 | R55: =D55+Q55 -> -36486.274
A56: USD | B56: LAM_STG_SP_INT | C56: 46259 | D56: 292572.12 | E56: 2.1045551e+09 | F56: -22001692 | G56: -2549517.2 | H56: =E56+F56 -> 2.0825534e+09 | I56: =(H56-H55-G56)/(H55+G56) -> 0.00014050695 | J56: =J55*(1+I56) -> 100.71463 | K56: =H56-H55-G56 -> 292572.12 | L56: =K56-D56 -> -2.7725473e-06 | O56: -2034.6654 | P56: =D56+O56 -> 290537.46 | Q56: =$Q$54*(C56-C55)*E56/E55 -> -233236.07 | R56: =D56+Q56 -> 59336.049
A57: USD | B57: LAM_STG_SP_INT | C57: 46260 | D57: 333748.75 | E57: 2.1049355e+09 | F57: -22048183 | G57: 184.85257 | H57: =E57+F57 -> 2.0828873e+09 | I57: =(H57-H56-G57)/(H56+G57) -> 0.00016025938 | J57: =J56*(1+I57) -> 100.73077 | K57: =H57-H56-G57 -> 333748.75 | L57: =K57-D57 -> 1.4666002e-06 | O57: -2299.1326 | P57: =D57+O57 -> 331449.61 | Q57: =$Q$54*(C57-C56)*E57/E56 -> -233009.88 | R57: =D57+Q57 -> 100738.86
A58: USD | B58: LAM_STG_SP_INT | C58: 46261 | D58: 340538.55 | E58: 2.1883475e+09 | F58: -1.3783132e+08 | G58: -32711676 | H58: =E58+F58 -> 2.0505162e+09 | I58: =(H58-H57-G58)/(H57+G58) -> 0.00016610213 | J58: =J57*(1+I58) -> 100.7475 | K58: =H58-H57-G58 -> 340538.55 | L58: =K58-D58 -> -1.0412186e-06 | O58: -2578.9147 | P58: =D58+O58 -> 337959.63 | Q58: =$Q$54*(C58-C57)*E58/E57 -> -242199.55 | R58: =D58+Q58 -> 98338.994
A59: USD | B59: LAM_STG_SP_INT | C59: 46262 | D59: 174693.48 | E59: 2.1888631e+09 | F59: -1.388808e+08 | G59: -708545.83 | H59: =E59+F59 -> 2.0499823e+09 | I59: =(H59-H58-G59)/(H58+G59) -> 8.5224331e-05 | J59: =J58*(1+I59) -> 100.75609 | K59: =H59-H58-G59 -> 174693.48 | L59: =K59-D59 -> 2.8349459e-06 | O59: -6861.146 | P59: =D59+O59 -> 167832.34 | Q59: =$Q$54*(C59-C58)*E59/E58 -> -233022.66 | R59: =D59+Q59 -> -58329.177
A60: USD | B60: LAM_STG_SP_INT | C60: 46265 | D60: 630602.15 | E60: 2.2018836e+09 | F60: -1.6358606e+08 | G60: -12315432 | H60: =E60+F60 -> 2.0382975e+09 | I60: =(H60-H59-G60)/(H59+G60) -> 0.00030947264 | J60: =J59*(1+I60) -> 100.78727 | K60: =H60-H59-G60 -> 630602.15 | L60: =K60-D60 -> -1.6170088e-06 | O60: -17081.234 | P60: =D60+O60 -> 613520.92 | Q60: =$Q$54*(C60-C59)*E60/E59 -> -703060.73 | R60: =D60+Q60 -> -72458.58
A61: USD | B61: LAM_STG_SP_INT | C61: 46266 | D61: 201303.55 | E61: 2.2087821e+09 | F61: -1.771878e+08 | G61: -6904520.5 | H61: =E61+F61 -> 2.0315943e+09 | I61: =(H61-H60-G61)/(H60+G61) -> 9.9096311e-05 | J61: =J60*(1+I61) -> 100.79726 | K61: =H61-H60-G61 -> 201303.55 | L61: =K61-D61 -> 2.7269125e-06 | O61: -7457.0645 | P61: =D61+O61 -> 193846.49 | Q61: =$Q$54*(C61-C60)*E61/E60 -> -233697.66 | R61: =D61+Q61 -> -32394.108
A62: USD | B62: LAM_STG_SP_INT | C62: 46267 | D62: 321664.49 | E62: 2.2094274e+09 | F62: -1.7751079e+08 | G62: 653.08478 | H62: =E62+F62 -> 2.0319166e+09 | I62: =(H62-H61-G62)/(H61+G62) -> 0.00015833101 | J62: =J61*(1+I62) -> 100.81322 | K62: =H62-H61-G62 -> 321664.49 | L62: =K62-D62 -> -1.5627593e-06 | O62: -8122.7729 | P62: =D62+O62 -> 313541.71 | Q62: =$Q$54*(C62-C61)*E62/E61 -> -233035.83 | R62: =D62+Q62 -> 88628.654
A63: USD | B63: LAM_STG_SP_INT | C63: 46268 | D63: 452746.99 | E63: 2.2102714e+09 | F63: -1.7790143e+08 | G63: 653.14968 | H63: =E63+F63 -> 2.03237e+09 | I63: =(H63-H62-G63)/(H62+G63) -> 0.00022281763 | J63: =J62*(1+I63) -> 100.83568 | K63: =H63-H62-G63 -> 452746.99 | L63: =K63-D63 -> -3.7075952e-06 | O63: -8103.1918 | P63: =D63+O63 -> 444643.8 | Q63: =$Q$54*(C63-C62)*E63/E62 -> -233056.77 | R63: =D63+Q63 -> 219690.22
A64: USD | B64: LAM_STG_SP_INT | C64: 46269 | D64: 300859.65 | E64: 2.2404764e+09 | F64: -2.0780488e+08 | G64: 653.21422 | H64: =E64+F64 -> 2.0326715e+09 | I64: =(H64-H63-G64)/(H63+G64) -> 0.00014803385 | J64: =J63*(1+I64) -> 100.85061 | K64: =H64-H63-G64 -> 300859.65 | L64: =K64-D64 -> 1.2984965e-06 | O64: -10095.67 | P64: =D64+O64 -> 290763.98 | Q64: =$Q$54*(C64-C63)*E64/E63 -> -236151.44 | R64: =D64+Q64 -> 64708.205
